Workbook
Name Slicer_Diabetes_Level: #N/A
Name Slicer_smoker: #N/A

Sheet Customer Names
A1: Customer ID | B1: name | C1: title | D1: first_name | E1: last_name
A2: Id1 | B2: Hawks, Ms. Kelly | C2: =LEFT(TRIM(MID(B2, FIND(",", B2)+1, 100)), FIND(" ", TRIM(MID(B2, FIND(",", B2)+1, 100)))-1) -> Ms. | D2: =TRIM(RIGHT(TRIM(MID(B2, FIND(",", B2)+1, 99)), LEN(TRIM(MID(B2, FIND(",", B2)+1, 99))) - FIND(" ", TRIM(MID(B2, FIND(",", B2)+1, 99))))) -> Kelly | E2: =LEFT(TRIM(B2), FIND(", ", TRIM(B2) & " ") - 1) -> Hawks | F2: =LEN(D2) -> 5
A3: Id2 | B3: Lehner, Mr. Matthew D | C3: =LEFT(TRIM(MID(B3, FIND(",", B3)+1, 100)), FIND(" ", TRIM(MID(B3, FIND(",", B3)+1, 100)))-1) -> Mr. | D3: =TRIM(RIGHT(TRIM(MID(B3, FIND(",", B3)+1, 99)), LEN(TRIM(MID(B3, FIND(",", B3)+1, 99))) - FIND(" ", TRIM(MID(B3, FIND(",", B3)+1, 99))))) -> Matthew D | E3: =LEFT(TRIM(B3), FIND(", ", TRIM(B3) & " ") - 1) -> Lehner
A4: Id3 | B4: Lu, Mr. Phil | C4: =LEFT(TRIM(MID(B4, FIND(",", B4)+1, 100)), FIND(" ", TRIM(MID(B4, FIND(",", B4)+1, 100)))-1) -> Mr. | D4: =TRIM(RIGHT(TRIM(MID(B4, FIND(",", B4)+1, 99)), LEN(TRIM(MID(B4, FIND(",", B4)+1, 99))) - FIND(" ", TRIM(MID(B4, FIND(",", B4)+1, 99))))) -> Phil | E4: =LEFT(TRIM(B4), FIND(", ", TRIM(B4) & " ") - 1) -> Lu
A5: Id4 | B5: Osborne, Ms. Kelsey | C5: =LEFT(TRIM(MID(B5, FIND(",", B5)+1, 100)), FIND(" ", TRIM(MID(B5, FIND(",", B5)+1, 100)))-1) -> Ms. | D5: =TRIM(RIGHT(TRIM(MID(B5, FIND(",", B5)+1, 99)), LEN(TRIM(MID(B5, FIND(",", B5)+1, 99))) - FIND(" ", TRIM(MID(B5, FIND(",", B5)+1, 99))))) -> Kelsey | E5: =LEFT(TRIM(B5), FIND(", ", TRIM(B5) & " ") - 1) -> Osborne
A6: Id5 | B6: Kadala, Ms. Kristyn | C6: =LEFT(TRIM(MID(B6, FIND(",", B6)+1, 100)), FIND(" ", TRIM(MID(B6, FIND(",", B6)+1, 100)))-1) -> Ms. | D6: =TRIM(RIGHT(TRIM(MID(B6, FIND(",", B6)+1, 99)), LEN(TRIM(MID(B6, FIND(",", B6)+1, 99))) - FIND(" ", TRIM(MID(B6, FIND(",", B6)+1, 99))))) -> Kristyn | E6: =LEFT(TRIM(B6), FIND(", ", TRIM(B6) & " ") - 1) -> Kadala
A7: Id6 | B7: Baker, Mr. Russell B. | C7: =LEFT(TRIM(MID(B7, FIND(",", B7)+1, 100)), FIND(" ", TRIM(MID(B7, FIND(",", B7)+1, 100)))-1) -> Mr. | D7: =TRIM(RIGHT(TRIM(MID(B7, FIND(",", B7)+1, 99)), LEN(TRIM(MID(B7, FIND(",", B7)+1, 99))) - FIND(" ", TRIM(MID(B7, FIND(",", B7)+1, 99))))) -> Russell B. | E7: =LEFT(TRIM(B7), FIND(", ", TRIM(B7) & " ") - 1) -> Baker
A8: Id7 | B8: Macpherson, Mr. Scott | C8: =LEFT(TRIM(MID(B8, FIND(",", B8)+1, 100)), FIND(" ", TRIM(MID(B8, FIND(",", B8)+1, 100)))-1) -> Mr. | D8: =TRIM(RIGHT(TRIM(MID(B8, FIND(",", B8)+1, 99)), LEN(TRIM(MID(B8, FIND(",", B8)+1, 99))) - FIND(" ", TRIM(MID(B8, FIND(",", B8)+1, 99))))) -> Scott | E8: =LEFT(TRIM(B8), FIND(", ", TRIM(B8) & " ") - 1) -> Macpherson
A9: Id8 | B9: Hallman, Mr. Stephen | C9: =LEFT(TRIM(MID(B9, FIND(",", B9)+1, 100)), FIND(" ", TRIM(MID(B9, FIND(",", B9)+1, 100)))-1) -> Mr. | D9: =TRIM(RIGHT(TRIM(MID(B9, FIND(",", B9)+1, 99)), LEN(TRIM(MID(B9, FIND(",", B9)+1, 99))) - FIND(" ", TRIM(MID(B9, FIND(",", B9)+1, 99))))) -> Stephen | E9: =LEFT(TRIM(B9), FIND(", ", TRIM(B9) & " ") - 1) -> Hallman
A10: Id9 | B10: Moran, Mr. Patrick R. | C10: =LEFT(TRIM(MID(B10, FIND(",", B10)+1, 100)), FIND(" ", TRIM(MID(B10, FIND(",", B10)+1, 100)))-1) -> Mr. | D10: =TRIM(RIGHT(TRIM(MID(B10, FIND(",", B10)+1, 99)), LEN(TRIM(MID(B10, FIND(",", B10)+1, 99))) - FIND(" ", TRIM(MID(B10, FIND(",", B10)+1, 99))))) -> Patrick R. | E10: =LEFT(TRIM(B10), FIND(", ", TRIM(B10) & " ") - 1) -> Moran
A11: Id10 | B11: Benner, Ms. Brooke N. | C11: =LEFT(TRIM(MID(B11, FIND(",", B11)+1, 100)), FIND(" ", TRIM(MID(B11, FIND(",", B11)+1, 100)))-1) -> Ms. | D11: =TRIM(RIGHT(TRIM(MID(B11, FIND(",", B11)+1, 99)), LEN(TRIM(MID(B11, FIND(",", B11)+1, 99))) - FIND(" ", TRIM(MID(B11, FIND(",", B11)+1, 99))))) -> Brooke N. | E11: =LEFT(TRIM(B11), FIND(", ", TRIM(B11) & " ") - 1) -> Benner
A12: Id11 | B12: Fierro Vargas, Ms. Paola Andrea | C12: =LEFT(TRIM(MID(B12, FIND(",", B12)+1, 100)), FIND(" ", TRIM(MID(B12, FIND(",", B12)+1, 100)))-1) -> Ms. | D12: =TRIM(RIGHT(TRIM(MID(B12, FIND(",", B12)+1, 99)), LEN(TRIM(MID(B12, FIND(",", B12)+1, 99))) - FIND(" ", TRIM(MID(B12, FIND(",", B12)+1, 99))))) -> Paola Andrea | E12: =LEFT(TRIM(B12), FIND(", ", TRIM(B12) & " ") - 1) -> Fierro Vargas
A13: Id12 | B13: Franz, Mr. David | C13: =LEFT(TRIM(MID(B13, FIND(",", B13)+1, 100)), FIND(" ", TRIM(MID(B13, FIND(",", B13)+1, 100)))-1) -> Mr. | D13: =TRIM(RIGHT(TRIM(MID(B13, FIND(",", B13)+1, 99)), LEN(TRIM(MID(B13, FIND(",", B13)+1, 99))) - FIND(" ", TRIM(MID(B13, FIND(",", B13)+1, 99))))) -> David | E13: =LEFT(TRIM(B13), FIND(", ", TRIM(B13) & " ") - 1) -> Franz
A14: Id13 | B14: Foster, Mr. Wade | C14: =LEFT(TRIM(MID(B14, FIND(",", B14)+1, 100)), FIND(" ", TRIM(MID(B14, FIND(",", B14)+1, 100)))-1) -> Mr. | D14: =TRIM(RIGHT(TRIM(MID(B14, FIND(",", B14)+1, 99)), LEN(TRIM(MID(B14, FIND(",", B14)+1, 99))) - FIND(" ", TRIM(MID(B14, FIND(",", B14)+1, 99))))) -> Wade | E14: =LEFT(TRIM(B14), FIND(", ", TRIM(B14) & " ") - 1) -> Foster
... A2336: Id2335 | B2336: German, Mr. Aaron K | C2336: =LEFT(TRIM(MID(B2336, FIND(",", B2336)+1, 100)), FIND(" ", TRIM(MID(B2336, FIND(",", B2336)+1, 100)))-1) -> Mr. | D2336: =TRIM(RIGHT(TRIM(MID(B2336, FIND(",", B2336)+1, 99)), LEN(TRIM(MID(B2336, FIND(",", B2336)+1, 99))) - FIND(" ", TRIM(MID(B2336, FIND(",", B2336)+1, 99))))) -> Aaron K | E2336: =LEFT(TRIM(B2336), FIND(", ", TRIM(B2336) & " ") - 1) -> German

Sheet Medical Examinations
A1: Customer ID | B1: BMI | C1: HBA1C | D1: Heart Issues | E1: Any Transplants | F1: Cancer history | G1: NumberOfMajorSurgeries | H1: smoker | I1: count_blank | J1: no of surgery | K1: BMI_category | L1: smoker_missing
A2: Id1 | B2: 47.41 | C2: 7.47 | D2: No | E2: No | F2: No | G2: No major surgery | H2: yes | I2: =COUNTIF(A2:H2, "?") -> 0 | J2: =IF(OR(G2="No major surgery"),0,G2) -> 0 | K2: =IF(B7<18.5,"Underweight", IF(B7<25,"Normal Weight", IF(B7<30,"Overweight", "Obesity"))) -> Obesity | L2: {=IF(H2="?",INDEX($H$2:$H$2336,MODE(MATCH($H$2:$H$2336,$H$2:$H$2336,0))),H2)} -> yes
A3: Id2 | B3: 30.36 | C3: 5.77 | D3: No | E3: No | F3: No | G3: No major surgery | H3: yes | I3: =COUNTIF(A3:H3, "?") -> 0 | J3: =IF(OR(G3="No major surgery"),0,G3) -> 0 | K3: =IF(B3<18.5,"Underweight", IF(B3<25,"Normal Weight", IF(B3<30,"Overweight", "Obesity"))) -> Obesity | L3: {=IF(H3="?",INDEX($H$2:$H$2336,MODE(MATCH($H$2:$H$2336,$H$2:$H$2336,0))),H3)} -> yes
A4: Id3 | B4: 34.485 | C4: 11.87 | D4: yes | E4: No | F4: No | G4: 2 | H4: yes | I4: =COUNTIF(A4:H4, "?") -> 0 | J4: =IF(OR(G4="No major surgery"),0,G4) -> 2 | K4: =IF(B4<18.5,"Underweight", IF(B4<25,"Normal Weight", IF(B4<30,"Overweight", "Obesity"))) -> Obesity | L4: {=IF(H4="?",INDEX($H$2:$H$2336,MODE(MATCH($H$2:$H$2336,$H$2:$H$2336,0))),H4)} -> yes
A5: Id4 | B5: 38.095 | C5: 6.05 | D5: No | E5: No | F5: No | G5: No major surgery | H5: yes | I5: =COUNTIF(A5:H5, "?") -> 0 | J5: =IF(OR(G5="No major surgery"),0,G5) -> 0 | K5: =IF(B5<18.5,"Underweight", IF(B5<25,"Normal Weight", IF(B5<30,"Overweight", "Obesity"))) -> Obesity | L5: {=IF(H5="?",INDEX($H$2:$H$2336,MODE(MATCH($H$2:$H$2336,$H$2:$H$2336,0))),H5)} -> yes
A6: Id5 | B6: 35.53 | C6: 5.45 | D6: No | E6: No | F6: No | G6: No major surgery | H6: yes | I6: =COUNTIF(A6:H6, "?") -> 0 | J6: =IF(OR(G6="No major surgery"),0,G6) -> 0 | K6: =IF(B6<18.5,"Underweight", IF(B6<25,"Normal Weight", IF(B6<30,"Overweight", "Obesity"))) -> Obesity | L6: {=IF(H6="?",INDEX($H$2:$H$2336,MODE(MATCH($H$2:$H$2336,$H$2:$H$2336,0))),H6)} -> yes
A7: Id6 | B7: 32.8 | C7: 6.59 | D7: No | E7: No | F7: No | G7: No major surgery | H7: yes | I7: =COUNTIF(A7:H7, "?") -> 0 | J7: =IF(OR(G7="No major surgery"),0,G7) -> 0 | K7: =IF(B7<18.5,"Underweight", IF(B7<25,"Normal Weight", IF(B7<30,"Overweight", "Obesity"))) -> Obesity | L7: {=IF(H7="?",INDEX($H$2:$H$2336,MODE(MATCH($H$2:$H$2336,$H$2:$H$2336,0))),H7)} -> yes
A8: Id7 | B8: 36.4 | C8: 6.07 | D8: No | E8: No | F8: No | G8: No major surgery | H8: yes | I8: =COUNTIF(A8:H8, "?") -> 0 | J8: =IF(OR(G8="No major surgery"),0,G8) -> 0 | K8: =IF(B8<18.5,"Underweight", IF(B8<25,"Normal Weight", IF(B8<30,"Overweight", "Obesity"))) -> Obesity | L8: {=IF(H8="?",INDEX($H$2:$H$2336,MODE(MATCH($H$2:$H$2336,$H$2:$H$2336,0))),H8)} -> yes
A9: Id8 | B9: 36.96 | C9: 7.93 | D9: No | E9: No | F9: No | G9: 3 | H9: yes | I9: =COUNTIF(A9:H9, "?") -> 0 | J9: =IF(OR(G9="No major surgery"),0,G9) -> 3 | K9: =IF(B9<18.5,"Underweight", IF(B9<25,"Normal Weight", IF(B9<30,"Overweight", "Obesity"))) -> Obesity | L9: {=IF(H9="?",INDEX($H$2:$H$2336,MODE(MATCH($H$2:$H$2336,$H$2:$H$2336,0))),H9)} -> yes
A10: Id9 | B10: 41.14 | C10: 9.58 | D10: yes | E10: No | F10: Yes | G10: 1 | H10: yes | I10: =COUNTIF(A10:H10, "?") -> 0 | J10: =IF(OR(G10="No major surgery"),0,G10) -> 1 | K10: =IF(B10<18.5,"Underweight", IF(B10<25,"Normal Weight", IF(B10<30,"Overweight", "Obesity"))) -> Obesity | L10: {=IF(H10="?",INDEX($H$2:$H$2336,MODE(MATCH($H$2:$H$2336,$H$2:$H$2336,0))),H10)} -> yes
A11: Id10 | B11: 38.06 | C11: 10.79 | D11: No | E11: No | F11: No | G11: No major surgery | H11: yes | I11: =COUNTIF(A11:H11, "?") -> 0 | J11: =IF(OR(G11="No major surgery"),0,G11) -> 0 | K11: =IF(B11<18.5,"Underweight", IF(B11<25,"Normal Weight", IF(B11<30,"Overweight", "Obesity"))) -> Obesity | L11: {=IF(H11="?",INDEX($H$2:$H$2336,MODE(MATCH($H$2:$H$2336,$H$2:$H$2336,0))),H11)} -> yes
A12: Id11 | B12: 37.7 | C12: 5.96 | D12: yes | E12: No | F12: No | G12: 2 | H12: yes | I12: =COUNTIF(A12:H12, "?") -> 0 | J12: =IF(OR(G12="No major surgery"),0,G12) -> 2 | K12: =IF(B12<18.5,"Underweight", IF(B12<25,"Normal Weight", IF(B12<30,"Overweight", "Obesity"))) -> Obesity | L12: {=IF(H12="?",INDEX($H$2:$H$2336,MODE(MATCH($H$2:$H$2336,$H$2:$H$2336,0))),H12)} -> yes
A13: Id12 | B13: 42.13 | C13: 11.9 | D13: No | E13: No | F13: No | G13: No major surgery | H13: yes | I13: =COUNTIF(A13:H13, "?") -> 0 | J13: =IF(OR(G13="No major surgery"),0,G13) -> 0 | K13: =IF(B13<18.5,"Underweight", IF(B13<25,"Normal Weight", IF(B13<30,"Overweight", "Obesity"))) -> Obesity | L13: {=IF(H13="?",INDEX($H$2:$H$2336,MODE(MATCH($H$2:$H$2336,$H$2:$H$2336,0))),H13)} -> yes
A14: Id13 | B14: 40.92 | C14: 8.41 | D14: No | E14: No | F14: No | G14: No major surgery | H14: yes | I14: =COUNTIF(A14:H14, "?") -> 0 | J14: =IF(OR(G14="No major surgery"),0,G14) -> 0 | K14: =IF(B14<18.5,"Underweight", IF(B14<25,"Normal Weight", IF(B14<30,"Overweight", "Obesity"))) -> Obesity | L14: {=IF(H14="?",INDEX($H$2:$H$2336,MODE(MATCH($H$2:$H$2336,$H$2:$H$2336,0))),H14)} -> yes
A15: Id14 | B15: 40.565 | C15: 7.02 | D15: No | E15: No | F15: No | G15: No major surgery | H15: yes | I15: =COUNTIF(A15:H15, "?") -> 0 | J15: =IF(OR(G15="No major surgery"),0,G15) -> 0 | K15: =IF(B15<18.5,"Underweight", IF(B15<25,"Normal Weight", IF(B15<30,"Overweight", "Obesity"))) -> Obesity | L15: {=IF(H15="?",INDEX($H$2:$H$2336,MODE(MATCH($H$2:$H$2336,$H$2:$H$2336,0))),H15)} -> yes
A16: Id15 | B16: 36.385 | C16: 7.59 | D16: yes | E16: No | F16: No | G16: 2 | H16: yes | I16: =COUNTIF(A16:H16, "?") -> 0 | J16: =IF(OR(G16="No major surgery"),0,G16) -> 2 | K16: =IF(B16<18.5,"Underweight", IF(B16<25,"Normal Weight", IF(B16<30,"Overweight", "Obesity"))) -> Obesity | L16: {=IF(H16="?",INDEX($H$2:$H$2336,MODE(MATCH($H$2:$H$2336,$H$2:$H$2336,0))),H16)} -> yes
A17: Id16 | B17: 39.9 | C17: 11.32 | D17: No | E17: No | F17: No | G17: No major surgery | H17: yes | I17: =COUNTIF(A17:H17, "?") -> 0 | J17: =IF(OR(G17="No major surgery"),0,G17) -> 0 | K17: =IF(B17<18.5,"Underweight", IF(B17<25,"Normal Weight", IF(B17<30,"Overweight", "Obesity"))) -> Obesity | L17: {=IF(H17="?",INDEX($H$2:$H$2336,MODE(MATCH($H$2:$H$2336,$H$2:$H$2336,0))),H17)} -> yes
A18: Id17 | B18: 33.8 | C18: 7.67 | D18: No | E18: No | F18: No | G18: 3 | H18: yes | I18: =COUNTIF(A18:H18, "?") -> 0 | J18: =IF(OR(G18="No major surgery"),0,G18) -> 3 | K18: =IF(B18<18.5,"Underweight", IF(B18<25,"Normal Weight", IF(B18<30,"Overweight", "Obesity"))) -> Obesity | L18: {=IF(H18="?",INDEX($H$2:$H$2336,MODE(MATCH($H$2:$H$2336,$H$2:$H$2336,0))),H18)} -> yes
A19: Id18 | B19: 36.765 | C19: 7.29 | D19: yes | E19: No | F19: Yes | G19: 1 | H19: yes | I19: =COUNTIF(A19:H19, "?") -> 0 | J19: =IF(OR(G19="No major surgery"),0,G19) -> 1 | K19: =IF(B19<18.5,"Underweight", IF(B19<25,"Normal Weight", IF(B19<30,"Overweight", "Obesity"))) -> Obesity | L19: {=IF(H19="?",INDEX($H$2:$H$2336,MODE(MATCH($H$2:$H$2336,$H$2:$H$2336,0))),H19)} -> yes
A20: Id19 | B20: 36.955 | C20: 4.72 | D20: yes | E20: No | F20: No | G20: 1 | H20: yes | I20: =COUNTIF(A20:H20, "?") -> 0 | J20: =IF(OR(G20="No major surgery"),0,G20) -> 1 | K20: =IF(B20<18.5,"Underweight", IF(B20<25,"Normal Weight", IF(B20<30,"Overweight", "Obesity"))) -> Obesity | L20: {=IF(H20="?",INDEX($H$2:$H$2336,MODE(MATCH($H$2:$H$2336,$H$2:$H$2336,0))),H20)} -> yes
A21: Id20 | B21: 42.9 | C21: 11.41 | D21: No | E21: No | F21: No | G21: No major surgery | H21: yes | I21: =COUNTIF(A21:H21, "?") -> 0 | J21: =IF(OR(G21="No major surgery"),0,G21) -> 0 | K21: =IF(B21<18.5,"Underweight", IF(B21<25,"Normal Weight", IF(B21<30,"Overweight", "Obesity"))) -> Obesity | L21: {=IF(H21="?",INDEX($H$2:$H$2336,MODE(MATCH($H$2:$H$2336,$H$2:$H$2336,0))),H21)} -> yes
A22: Id21 | B22: 36.3 | C22: 11.5 | D22: yes | E22: No | F22: No | G22: 2 | H22: yes | I22: =COUNTIF(A22:H22, "?") -> 0 | J22: =IF(OR(G22="No major surgery"),0,G22) -> 2 | K22: =IF(B22<18.5,"Underweight", IF(B22<25,"Normal Weight", IF(B22<30,"Overweight", "Obesity"))) -> Obesity | L22: {=IF(H22="?",INDEX($H$2:$H$2336,MODE(MATCH($H$2:$H$2336,$H$2:$H$2336,0))),H22)} -> yes
A23: Id22 | B23: 32.2 | C23: 6.22 | D23: yes | E23: No | F23: No | G23: 2 | H23: yes | I23: =COUNTIF(A23:H23, "?") -> 0 | J23: =IF(OR(G23="No major surgery"),0,G23) -> 2 | K23: =IF(B23<18.5,"Underweight", IF(B23<25,"Normal Weight", IF(B23<30,"Overweight", "Obesity"))) -> Obesity | L23: {=IF(H23="?",INDEX($H$2:$H$2336,MODE(MATCH($H$2:$H$2336,$H$2:$H$2336,0))),H23)} -> yes
A24: Id23 | B24: 31.3 | C24: 11.38 | D24: No | E24: No | F24: No | G24: 3 | H24: yes | I24: =COUNTIF(A24:H24, "?") -> 0 | J24: =IF(OR(G24="No major surgery"),0,G24) -> 3 | K24: =IF(B24<18.5,"Underweight", IF(B24<25,"Normal Weight", IF(B24<30,"Overweight", "Obesity"))) -> Obesity | L24: {=IF(H24="?",INDEX($H$2:$H$2336,MODE(MATCH($H$2:$H$2336,$H$2:$H$2336,0))),H24)} -> yes
A25: Id24 | B25: 41.8 | C25: 7.89 | D25: yes | E25: No | F25: No | G25: 2 | H25: yes | I25: =COUNTIF(A25:H25, "?") -> 0 | J25: =IF(OR(G25="No major surgery"),0,G25) -> 2 | K25: =IF(B25<18.5,"Underweight", IF(B25<25,"Normal Weight", IF(B25<30,"Overweight", "Obesity"))) -> Obesity | L25: {=IF(H25="?",INDEX($H$2:$H$2336,MODE(MATCH($H$2:$H$2336,$H$2:$H$2336,0))),H25)} -> yes
A26: Id25 | B26: 35.09 | C26: 4.38 | D26: yes | E26: No | F26: No | G26: 2 | H26: yes | I26: =COUNTIF(A26:H26, "?") -> 0 | J26: =IF(OR(G26="No major surgery"),0,G26) -> 2 | K26: =IF(B26<18.5,"Underweight", IF(B26<25,"Normal Weight", IF(B26<30,"Overweight", "Obesity"))) -> Obesity | L26: {=IF(H26="?",INDEX($H$2:$H$2336,MODE(MATCH($H$2:$H$2336,$H$2:$H$2336,0))),H26)} -> yes
A27: Id26 | B27: 33.88 | C27: 7.01 | D27: No | E27: No | F27: No | G27: 3 | H27: yes | I27: =COUNTIF(A27:H27, "?") -> 0 | J27: =IF(OR(G27="No major surgery"),0,G27) -> 3 | K27: =IF(B27<18.5,"Underweight", IF(B27<25,"Normal Weight", IF(B27<30,"Overweight", "Obesity"))) -> Obesity | L27: {=IF(H27="?",INDEX($H$2:$H$2336,MODE(MATCH($H$2:$H$2336,$H$2:$H$2336,0))),H27)} -> yes
A28: Id27 | B28: 30.875 | C28: 11.88 | D28: No | E28: No | F28: No | G28: No major surgery | H28: yes | I28: =COUNTIF(A28:H28, "?") -> 0 | J28: =IF(OR(G28="No major surgery"),0,G28) -> 0 | K28: =IF(B28<18.5,"Underweight", IF(B28<25,"Normal Weight", IF(B28<30,"Overweight", "Obesity"))) -> Obesity | L28: {=IF(H28="?",INDEX($H$2:$H$2336,MODE(MATCH($H$2:$H$2336,$H$2:$H$2336,0))),H28)} -> yes
A29: Id28 | B29: 36.86 | C29: 5.19 | D29: yes | E29: No | F29: Yes | G29: 1 | H29: yes | I29: =COUNTIF(A29:H29, "?") -> 0 | J29: =IF(OR(G29="No major surgery"),0,G29) -> 1 | K29: =IF(B29<18.5,"Underweight", IF(B29<25,"Normal Weight", IF(B29<30,"Overweight", "Obesity"))) -> Obesity | L29: {=IF(H29="?",INDEX($H$2:$H$2336,MODE(MATCH($H$2:$H$2336,$H$2:$H$2336,0))),H29)} -> yes
A30: Id29 | B30: 35.86 | C30: 6.74 | D30: yes | E30: No | F30: No | G30: 2 | H30: yes | I30: =COUNTIF(A30:H30, "?") -> 0 | J30: =IF(OR(G30="No major surgery"),0,G30) -> 2 | K30: =IF(B30<18.5,"Underweight", IF(B30<25,"Normal Weight", IF(B30<30,"Overweight", "Obesity"))) -> Obesity | L30: {=IF(H30="?",INDEX($H$2:$H$2336,MODE(MATCH($H$2:$H$2336,$H$2:$H$2336,0))),H30)} -> yes
A31: Id30 | B31: 37.05 | C31: 8.44 | D31: No | E31: No | F31: No | G31: No major surgery | H31: yes | I31: =COUNTIF(A31:H31, "?") -> 0 | J31: =IF(OR(G31="No major surgery"),0,G31) -> 0 | K31: =IF(B31<18.5,"Underweight", IF(B31<25,"Normal Weight", IF(B31<30,"Overweight", "Obesity"))) -> Obesity | L31: {=IF(H31="?",INDEX($H$2:$H$2336,MODE(MATCH($H$2:$H$2336,$H$2:$H$2336,0))),H31)} -> yes
A32: Id31 | B32: 43.89 | C32: 8.71 | D32: No | E32: No | F32: No | G32: No major surgery | H32: yes | I32: =COUNTIF(A32:H32, "?") -> 0 | J32: =IF(OR(G32="No major surgery"),0,G32) -> 0 | K32: =IF(B32<18.5,"Underweight", IF(B32<25,"Normal Weight", IF(B32<30,"Overweight", "Obesity"))) -> Obesity | L32: {=IF(H32="?",INDEX($H$2:$H$2336,MODE(MATCH($H$2:$H$2336,$H$2:$H$2336,0))),H32)} -> yes
A33: Id32 | B33: 42.35 | C33: 5.08 | D33: yes | E33: No | F33: No | G33: No major surgery | H33: yes | I33: =COUNTIF(A33:H33, "?") -> 0 | J33: =IF(OR(G33="No major surgery"),0,G33) -> 0 | K33: =IF(B33<18.5,"Underweight", IF(B33<25,"Normal Weight", IF(B33<30,"Overweight", "Obesity"))) -> Obesity | L33: {=IF(H33="?",INDEX($H$2:$H$2336,MODE(MATCH($H$2:$H$2336,$H$2:$H$2336,0))),H33)} -> yes
A34: Id33 | B34: 31.35 | C34: 6.86 | D34: No | E34: No | F34: No | G34: No major surgery | H34: yes | I34: =COUNTIF(A34:H34, "?") -> 0 | J34: =IF(OR(G34="No major surgery"),0,G34) -> 0 | K34: =IF(B34<18.5,"Underweight", IF(B34<25,"Normal Weight", IF(B34<30,"Overweight", "Obesity"))) -> Obesity | L34: {=IF(H34="?",INDEX($H$2:$H$2336,MODE(MATCH($H$2:$H$2336,$H$2:$H$2336,0))),H34)} -> yes
A35: Id34 | B35: 47.6 | C35: 5.95 | D35: yes | E35: No | F35: No | G35: No major surgery | H35: yes | I35: =COUNTIF(A35:H35, "?") -> 0 | J35: =IF(OR(G35="No major surgery"),0,G35) -> 0 | K35: =IF(B35<18.5,"Underweight", IF(B35<25,"Normal Weight", IF(B35<30,"Overweight", "Obesity"))) -> Obesity | L35: {=IF(H35="?",INDEX($H$2:$H$2336,MODE(MATCH($H$2:$H$2336,$H$2:$H$2336,0))),H35)} -> yes
A36: Id35 | B36: 46.2 | C36: 6.09 | D36: No | E36: No | F36: Yes | G36: 1 | H36: yes | I36: =COUNTIF(A36:H36, "?") -> 0 | J36: =IF(OR(G36="No major surgery"),0,G36) -> 1 | K36: =IF(B36<18.5,"Underweight", IF(B36<25,"Normal Weight", IF(B36<30,"Overweight", "Obesity"))) -> Obesity | L36: {=IF(H36="?",INDEX($H$2:$H$2336,MODE(MATCH($H$2:$H$2336,$H$2:$H$2336,0))),H36)} -> yes
A37: Id36 | B37: 32.015 | C37: 11.75 | D37: No | E37: No | F37: No | G37: No major surgery | H37: yes | I37: =COUNTIF(A37:H37, "?") -> 0 | J37: =IF(OR(G37="No major surgery"),0,G37) -> 0 | K37: =IF(B37<18.5,"Underweight", IF(B37<25,"Normal Weight", IF(B37<30,"Overweight", "Obesity"))) -> Obesity | L37: {=IF(H37="?",INDEX($H$2:$H$2336,MODE(MATCH($H$2:$H$2336,$H$2:$H$2336,0))),H37)} -> yes
A38: Id37 | B38: 40.565 | C38: 7.37 | D38: No | E38: No | F38: No | G38: No major surgery | H38: yes | I38: =COUNTIF(A38:H38, "?") -> 0 | J38: =IF(OR(G38="No major surgery"),0,G38) -> 0 | K38: =IF(B38<18.5,"Underweight", IF(B38<25,"Normal Weight", IF(B38<30,"Overweight", "Obesity"))) -> Obesity | L38: {=IF(H38="?",INDEX($H$2:$H$2336,MODE(MATCH($H$2:$H$2336,$H$2:$H$2336,0))),H38)} -> yes
A39: Id38 | B39: 32.45 | C39: 11.91 | D39: No | E39: No | F39: No | G39: No major surgery | H39: yes | I39: =COUNTIF(A39:H39, "?") -> 0 | J39: =IF(OR(G39="No major surgery"),0,G39) -> 0 | K39: =IF(B39<18.5,"Underweight", IF(B39<25,"Normal Weight", IF(B39<30,"Overweight", "Obesity"))) -> Obesity | L39: {=IF(H39="?",INDEX($H$2:$H$2336,MODE(MATCH($H$2:$H$2336,$H$2:$H$2336,0))),H39)} -> yes
A40: Id39 | B40: 34.96 | C40: 6.52 | D40: No | E40: No | F40: No | G40: No major surgery | H40: yes | I40: =COUNTIF(A40:H40, "?") -> 0 | J40: =IF(OR(G40="No major surgery"),0,G40) -> 0 | K40: =IF(B40<18.5,"Underweight", IF(B40<25,"Normal Weight", IF(B40<30,"Overweight", "Obesity"))) -> Obesity | L40: {=IF(H40="?",INDEX($H$2:$H$2336,MODE(MATCH($H$2:$H$2336,$H$2:$H$2336,0))),H40)} -> yes
...

Sheet Hospitalisation Details
A1: Customer ID | B1: year | C1: month | D1: date | E1: children | F1: charges | G1: Hospital tier | H1: City tier | I1: State ID | J1: count_blank | K1: customer_no | L1: month | M1: year_average | N1: hsplt_handled | O1: city_handled | P1: state_id | Q1: dd/mm/yy | R1: age | S1: charges | T1: Count
A2: Id2335 | B2: 1992 | C2: Jul | D2: 9 | E2: 0 | F2: 563.84 | G2: tier - 2 | H2: tier - 3 | I2: R1013 | J2: =COUNTIF(A2:I2, "?") -> 0 | K2: =IF(A2="?", "Unknown", A2) -> Id2335 | L2: =IF(C2="?", "Sep", C2) -> Jul | M2: =IF(B2="?",AVERAGE($B$2:$B$2344),B2) -> 1992 | N2: {=IF(G2="?",INDEX($G$2:$G$2344,MODE(MATCH($G$2:$G$2344,$G$2:$G$2344,0))),G2)} -> tier - 2 | O2: {=IF(H2="?",INDEX($H$2:$H$2344,MODE(MATCH($H$2:$H$2344,$H$2:$H$2344,0))),H2)} -> tier - 3 | P2: =IF(I2="?", "Unknown", I2) -> R1013 | Q2: =DATE(B2, MONTH(1 & L2), D2) -> 33794 | R2: =DATEDIF(Q2, DATE(2023,6,8), "Y") -> 30 | T2: =COUNTA(Table3[[#This Row],[month]:[age]]) -> 7
A3: Id2334 | B3: 1992 | C3: Nov | D3: 30 | E3: 0 | F3: 570.62 | G3: tier - 2 | H3: tier - 1 | I3: R1013 | J3: =COUNTIF(A3:I3, "?") -> 0 | K3: =IF(A3="?", "Unknown", A3) -> Id2334 | L3: =IF(C3="?", "Sep", C3) -> Nov | M3: =IF(B3="?",AVERAGE($B$2:$B$2344),B3) -> 1992 | N3: {=IF(G3="?",INDEX($G$2:$G$2344,MODE(MATCH($G$2:$G$2344,$G$2:$G$2344,0))),G3)} -> tier - 2 | O3: {=IF(H3="?",INDEX($H$2:$H$2344,MODE(MATCH($H$2:$H$2344,$H$2:$H$2344,0))),H3)} -> tier - 1 | P3: =IF(I3="?", "Unknown", I3) -> R1013 | Q3: =DATE(B3, MONTH(1 & L3), D3) -> 33938 | R3: =DATEDIF(Q3, DATE(2023,6,8), "Y") -> 30 | T3: =COUNTA(Table3[[#This Row],[month]:[age]]) -> 7
A4: Id2333 | B4: 1993 | C4: Jun | D4: 30 | E4: 0 | F4: 600 | G4: tier - 2 | H4: tier - 1 | I4: R1013 | J4: =COUNTIF(A4:I4, "?") -> 0 | K4: =IF(A4="?", "Unknown", A4) -> Id2333 | L4: =IF(C4="?", "Sep", C4) -> Jun | M4: =IF(B4="?",AVERAGE($B$2:$B$2344),B4) -> 1993 | N4: {=IF(G4="?",INDEX($G$2:$G$2344,MODE(MATCH($G$2:$G$2344,$G$2:$G$2344,0))),G4)} -> tier - 2 | O4: {=IF(H4="?",INDEX($H$2:$H$2344,MODE(MATCH($H$2:$H$2344,$H$2:$H$2344,0))),H4)} -> tier - 1 | P4: =IF(I4="?", "Unknown", I4) -> R1013 | Q4: =DATE(B4, MONTH(1 & L4), D4) -> 34150 | R4: =DATEDIF(Q4, DATE(2023,6,8), "Y") -> 29 | T4: =COUNTA(Table3[[#This Row],[month]:[age]]) -> 7
A5: Id2332 | B5: 1992 | C5: Sep | D5: 13 | E5: 0 | F5: 604.54 | G5: tier - 3 | H5: tier - 3 | I5: R1013 | J5: =COUNTIF(A5:I5, "?") -> 0 | K5: =IF(A5="?", "Unknown", A5) -> Id2332 | L5: =IF(C5="?", "Sep", C5) -> Sep | M5: =IF(B5="?",AVERAGE($B$2:$B$2344),B5) -> 1992 | N5: {=IF(G5="?",INDEX($G$2:$G$2344,MODE(MATCH($G$2:$G$2344,$G$2:$G$2344,0))),G5)} -> tier - 3 | O5: {=IF(H5="?",INDEX($H$2:$H$2344,MODE(MATCH($H$2:$H$2344,$H$2:$H$2344,0))),H5)} -> tier - 3 | P5: =IF(I5="?", "Unknown", I5) -> R1013 | Q5: =DATE(B5, MONTH(1 & L5), D5) -> 33860 | R5: =DATEDIF(Q5, DATE(2023,6,8), "Y") -> 30 | T5: =COUNTA(Table3[[#This Row],[month]:[age]]) -> 7
A6: Id2331 | B6: 1998 | C6: Jul | D6: 27 | E6: 0 | F6: 637.26 | G6: tier - 3 | H6: tier - 3 | I6: R1013 | J6: =COUNTIF(A6:I6, "?") -> 0 | K6: =IF(A6="?", "Unknown", A6) -> Id2331 | L6: =IF(C6="?", "Sep", C6) -> Jul | M6: =IF(B6="?",AVERAGE($B$2:$B$2344),B6) -> 1998 | N6: {=IF(G6="?",INDEX($G$2:$G$2344,MODE(MATCH($G$2:$G$2344,$G$2:$G$2344,0))),G6)} -> tier - 3 | O6: {=IF(H6="?",INDEX($H$2:$H$2344,MODE(MATCH($H$2:$H$2344,$H$2:$H$2344,0))),H6)} -> tier - 3 | P6: =IF(I6="?", "Unknown", I6) -> R1013 | Q6: =DATE(B6, MONTH(1 & L6), D6) -> 36003 | R6: =DATEDIF(Q6, DATE(2023,6,8), "Y") -> 24 | T6: =COUNTA(Table3[[#This Row],[month]:[age]]) -> 7
A7: Id2330 | B7: 2001 | C7: Nov | D7: 20 | E7: 0 | F7: 646.14 | G7: tier - 3 | H7: tier - 3 | I7: R1012 | J7: =COUNTIF(A7:I7, "?") -> 0 | K7: =IF(A7="?", "Unknown", A7) -> Id2330 | L7: =IF(C7="?", "Sep", C7) -> Nov | M7: =IF(B7="?",AVERAGE($B$2:$B$2344),B7) -> 2001 | N7: {=IF(G7="?",INDEX($G$2:$G$2344,MODE(MATCH($G$2:$G$2344,$G$2:$G$2344,0))),G7)} -> tier - 3 | O7: {=IF(H7="?",INDEX($H$2:$H$2344,MODE(MATCH($H$2:$H$2344,$H$2:$H$2344,0))),H7)} -> tier - 3 | P7: =IF(I7="?", "Unknown", I7) -> R1012 | Q7: =DATE(B7, MONTH(1 & L7), D7) -> 37215 | R7: =DATEDIF(Q7, DATE(2023,6,8), "Y") -> 21 | T7: =COUNTA(Table3[[#This Row],[month]:[age]]) -> 7
A8: Id2329 | B8: 1993 | C8: Jun | D8: 1 | E8: 0 | F8: 650 | G8: tier - 3 | H8: tier - 3 | I8: R1013 | J8: =COUNTIF(A8:I8, "?") -> 0 | K8: =IF(A8="?", "Unknown", A8) -> Id2329 | L8: =IF(C8="?", "Sep", C8) -> Jun | M8: =IF(B8="?",AVERAGE($B$2:$B$2344),B8) -> 1993 | N8: {=IF(G8="?",INDEX($G$2:$G$2344,MODE(MATCH($G$2:$G$2344,$G$2:$G$2344,0))),G8)} -> tier - 3 | O8: {=IF(H8="?",INDEX($H$2:$H$2344,MODE(MATCH($H$2:$H$2344,$H$2:$H$2344,0))),H8)} -> tier - 3 | P8: =IF(I8="?", "Unknown", I8) -> R1013 | Q8: =DATE(B8, MONTH(1 & L8), D8) -> 34121 | R8: =DATEDIF(Q8, DATE(2023,6,8), "Y") -> 30 | T8: =COUNTA(Table3[[#This Row],[month]:[age]]) -> 7
A9: Id2328 | B9: 1995 | C9: Jul | D9: 4 | E9: 0 | F9: 650 | G9: tier - 3 | H9: tier - 3 | I9: R1013 | J9: =COUNTIF(A9:I9, "?") -> 0 | K9: =IF(A9="?", "Unknown", A9) -> Id2328 | L9: =IF(C9="?", "Sep", C9) -> Jul | M9: =IF(B9="?",AVERAGE($B$2:$B$2344),B9) -> 1995 | N9: {=IF(G9="?",INDEX($G$2:$G$2344,MODE(MATCH($G$2:$G$2344,$G$2:$G$2344,0))),G9)} -> tier - 3 | O9: {=IF(H9="?",INDEX($H$2:$H$2344,MODE(MATCH($H$2:$H$2344,$H$2:$H$2344,0))),H9)} -> tier - 3 | P9: =IF(I9="?", "Unknown", I9) -> R1013 | Q9: =DATE(B9, MONTH(1 & L9), D9) -> 34884 | R9: =DATEDIF(Q9, DATE(2023,6,8), "Y") -> 27 | T9: =COUNTA(Table3[[#This Row],[month]:[age]]) -> 7
A10: Id2327 | B10: 2002 | C10: Nov | D10: 29 | E10: 0 | F10: 668 | G10: tier - 3 | H10: tier - 2 | I10: R1012 | J10: =COUNTIF(A10:I10, "?") -> 0 | K10: =IF(A10="?", "Unknown", A10) -> Id2327 | L10: =IF(C10="?", "Sep", C10) -> Nov | M10: =IF(B10="?",AVERAGE($B$2:$B$2344),B10) -> 2002 | N10: {=IF(G10="?",INDEX($G$2:$G$2344,MODE(MATCH($G$2:$G$2344,$G$2:$G$2344,0))),G10)} -> tier - 3 | O10: {=IF(H10="?",INDEX($H$2:$H$2344,MODE(MATCH($H$2:$H$2344,$H$2:$H$2344,0))),H10)} -> tier - 2 | P10: =IF(I10="?", "Unknown", I10) -> R1012 | Q10: =DATE(B10, MONTH(1 & L10), D10) -> 37589 | R10: =DATEDIF(Q10, DATE(2023,6,8), "Y") -> 20 | T10: =COUNTA(Table3[[#This Row],[month]:[age]]) -> 7
A11: Id2326 | B11: 1997 | C11: Nov | D11: 9 | E11: 0 | F11: 670 | G11: tier - 3 | H11: tier - 3 | I11: R1013 | J11: =COUNTIF(A11:I11, "?") -> 0 | K11: =IF(A11="?", "Unknown", A11) -> Id2326 | L11: =IF(C11="?", "Sep", C11) -> Nov | M11: =IF(B11="?",AVERAGE($B$2:$B$2344),B11) -> 1997 | N11: {=IF(G11="?",INDEX($G$2:$G$2344,MODE(MATCH($G$2:$G$2344,$G$2:$G$2344,0))),G11)} -> tier - 3 | O11: {=IF(H11="?",INDEX($H$2:$H$2344,MODE(MATCH($H$2:$H$2344,$H$2:$H$2344,0))),H11)} -> tier - 3 | P11: =IF(I11="?", "Unknown", I11) -> R1013 | Q11: =DATE(B11, MONTH(1 & L11), D11) -> 35743 | R11: =DATEDIF(Q11, DATE(2023,6,8), "Y") -> 25 | T11: =COUNTA(Table3[[#This Row],[month]:[age]]) -> 7
A12: Id2325 | B12: 2001 | C12: Sep | D12: 12 | E12: 0 | F12: 687.54 | G12: tier - 3 | H12: tier - 2 | I12: R1013 | J12: =COUNTIF(A12:I12, "?") -> 0 | K12: =IF(A12="?", "Unknown", A12) -> Id2325 | L12: =IF(C12="?", "Sep", C12) -> Sep | M12: =IF(B12="?",AVERAGE($B$2:$B$2344),B12) -> 2001 | N12: {=IF(G12="?",INDEX($G$2:$G$2344,MODE(MATCH($G$2:$G$2344,$G$2:$G$2344,0))),G12)} -> tier - 3 | O12: {=IF(H12="?",INDEX($H$2:$H$2344,MODE(MATCH($H$2:$H$2344,$H$2:$H$2344,0))),H12)} -> tier - 2 | P12: =IF(I12="?", "Unknown", I12) -> R1013 | Q12: =DATE(B12, MONTH(1 & L12), D12) -> 37146 | R12: =DATEDIF(Q12, DATE(2023,6,8), "Y") -> 21 | T12: =COUNTA(Table3[[#This Row],[month]:[age]]) -> 7
A13: Id2324 | B13: 1999 | C13: Dec | D13: 26 | E13: 0 | F13: 700 | G13: ? | H13: tier - 3 | I13: R1013 | J13: =COUNTIF(A13:I13, "?") -> 1 | K13: =IF(A13="?", "Unknown", A13) -> Id2324 | L13: =IF(C13="?", "Sep", C13) -> Dec | M13: =IF(B13="?",AVERAGE($B$2:$B$2344),B13) -> 1999 | N13: {=IF(G13="?",INDEX($G$2:$G$2344,MODE(MATCH($G$2:$G$2344,$G$2:$G$2344,0))),G13)} -> tier - 2 | O13: {=IF(H13="?",INDEX($H$2:$H$2344,MODE(MATCH($H$2:$H$2344,$H$2:$H$2344,0))),H13)} -> tier - 3 | P13: =IF(I13="?", "Unknown", I13) -> R1013 | Q13: =DATE(B13, MONTH(1 & L13), D13) -> 36520 | R13: =DATEDIF(Q13, DATE(2023,6,8), "Y") -> 23 | T13: =COUNTA(Table3[[#This Row],[month]:[age]]) -> 7
... A1050: Id1290 | B1050: 1977 | C1050: Jul | D1050: 26 | E1050: 2 | F1050: 8527.53 | G1050: tier - 2 | H1050: tier - 2 | I1050: R1013 | J1050: =COUNTIF(A1050:I1050, "?") -> 0 | K1050: =IF(A1050="?", "Unknown", A1050) -> Id1290 | L1050: =IF(C1050="?", "Sep", C1050) -> Jul | M1050: =IF(B1050="?",AVERAGE($B$2:$B$2344),B1050) -> 1977 | N1050: {=IF(G1050="?",INDEX($G$2:$G$2344,MODE(MATCH($G$2:$G$2344,$G$2:$G$2344,0))),G1050)} -> tier - 2 | O1050: {=IF(H1050="?",INDEX($H$2:$H$2344,MODE(MATCH($H$2:$H$2344,$H$2:$H$2344,0))),H1050)} -> tier - 2 | P1050: =IF(I1050="?", "Unknown", I1050) -> R1013 | Q1050: =DATE(B1050, MONTH(1 & L1050), D1050) -> 28332 | R1050: =DATEDIF(Q1050, DATE(2023,6,8), "Y") -> 45 | T1050: =COUNTA(Table3[[#This Row],[month]:[age]]) -> 7
A1051: Id1289 | B1051: ? | C1051: Jul | D1051: 24 | E1051: 0 | F1051: 8534.67 | G1051: tier - 2 | H1051: tier - 3 | I1051: R1024 | J1051: =COUNTIF(A1051:I1051, "?") -> 1 | K1051: =IF(A1051="?", "Unknown", A1051) -> Id1289 | L1051: =IF(C1051="?", "Sep", C1051) -> Jul | M1051: =IF(B1051="?",AVERAGE($B$2:$B$2344),B1051) -> 1982.8415 | N1051: {=IF(G1051="?",INDEX($G$2:$G$2344,MODE(MATCH($G$2:$G$2344,$G$2:$G$2344,0))),G1051)} -> tier - 2 | O1051: {=IF(H1051="?",INDEX($H$2:$H$2344,MODE(MATCH($H$2:$H$2344,$H$2:$H$2344,0))),H1051)} -> tier - 3 | P1051: =IF(I1051="?", "Unknown", I1051) -> R1024 | Q1051: =DATE(B1051, MONTH(1 & L1051), D1051) -> #VALUE! | R1051: =DATEDIF(Q1051, DATE(2023,6,8), "Y") -> #VALUE! | T1051: =COUNTA(Table3[[#This Row],[month]:[age]]) -> 7
A1052: Id1288 | B1052: 1981 | C1052: Dec | D1052: 27 | E1052: 3 | F1052: 8538.29 | G1052: tier - 2 | H1052: tier - 3 | I1052: R1024 | J1052: =COUNTIF(A1052:I1052, "?") -> 0 | K1052: =IF(A1052="?", "Unknown", A1052) -> Id1288 | L1052: =IF(C1052="?", "Sep", C1052) -> Dec | M1052: =IF(B1052="?",AVERAGE($B$2:$B$2344),B1052) -> 1981 | N1052: {=IF(G1052="?",INDEX($G$2:$G$2344,MODE(MATCH($G$2:$G$2344,$G$2:$G$2344,0))),G1052)} -> tier - 2 | O1052: {=IF(H1052="?",INDEX($H$2:$H$2344,MODE(MATCH($H$2:$H$2344,$H$2:$H$2344,0))),H1052)} -> tier - 3 | P1052: =IF(I1052="?", "Unknown", I1052) -> R1024 | Q1052: =DATE(B1052, MONTH(1 & L1052), D1052) -> 29947 | R1052: =DATEDIF(Q1052, DATE(2023,6,8), "Y") -> 41 | T1052: =COUNTA(Table3[[#This Row],[month]:[age]]) -> 7
A1053: Id1287 | B1053: 1975 | C1053: Nov | D1053: 6 | E1053: 1 | F1053: 8539.67 | G1053: tier - 2 | H1053: tier - 3 | I1053: R1011 | J1053: =COUNTIF(A1053:I1053, "?") -> 0 | K1053: =IF(A1053="?", "Unknown", A1053) -> Id1287 | L1053: =IF(C1053="?", "Sep", C1053) -> Nov | M1053: =IF(B1053="?",AVERAGE($B$2:$B$2344),B1053) -> 1975 | N1053: {=IF(G1053="?",INDEX($G$2:$G$2344,MODE(MATCH($G$2:$G$2344,$G$2:$G$2344,0))),G1053)} -> tier - 2 | O1053: {=IF(H1053="?",INDEX($H$2:$H$2344,MODE(MATCH($H$2:$H$2344,$H$2:$H$2344,0))),H1053)} -> tier - 3 | P1053: =IF(I1053="?", "Unknown", I1053) -> R1011 | Q1053: =DATE(B1053, MONTH(1 & L1053), D1053) -> 27704 | R1053: =DATEDIF(Q1053, DATE(2023,6,8), "Y") -> 47 | T1053: =COUNTA(Table3[[#This Row],[month]:[age]]) -> 7
A1054: Id1286 | B1054: ? | C1054: Dec | D1054: 12 | E1054: 1 | F1054: 8547.69 | G1054: tier - 2 | H1054: tier - 1 | I1054: R1013 | J1054: =COUNTIF(A1054:I1054, "?") -> 1 | K1054: =IF(A1054="?", "Unknown", A1054) -> Id1286 | L1054: =IF(C1054="?", "Sep", C1054) -> Dec | M1054: =IF(B1054="?",AVERAGE($B$2:$B$2344),B1054) -> 1982.8415 | N1054: {=IF(G1054="?",INDEX($G$2:$G$2344,MODE(MATCH($G$2:$G$2344,$G$2:$G$2344,0))),G1054)} -> tier - 2 | O1054: {=IF(H1054="?",INDEX($H$2:$H$2344,MODE(MATCH($H$2:$H$2344,$H$2:$H$2344,0))),H1054)} -> tier - 1 | P1054: =IF(I1054="?", "Unknown", I1054) -> R1013 | Q1054: =DATE(B1054, MONTH(1 & L1054), D1054) -> #VALUE! | R1054: =DATEDIF(Q1054, DATE(2023,6,8), "Y") -> #VALUE! | T1054: =COUNTA(Table3[[#This Row],[month]:[age]]) -> 7
A1055: Id1285 | B1055: 1975 | C1055: Aug | D1055: 6 | E1055: 1 | F1055: 8551.35 | G1055: tier - 2 | H1055: tier - 2 | I1055: R1011 | J1055: =COUNTIF(A1055:I1055, "?") -> 0 | K1055: =IF(A1055="?", "Unknown", A1055) -> Id1285 | L1055: =IF(C1055="?", "Sep", C1055) -> Aug | M1055: =IF(B1055="?",AVERAGE($B$2:$B$2344),B1055) -> 1975 | N1055: {=IF(G1055="?",INDEX($G$2:$G$2344,MODE(MATCH($G$2:$G$2344,$G$2:$G$2344,0))),G1055)} -> tier - 2 | O1055: {=IF(H1055="?",INDEX($H$2:$H$2344,MODE(MATCH($H$2:$H$2344,$H$2:$H$2344,0))),H1055)} -> tier - 2 | P1055: =IF(I1055="?", "Unknown", I1055) -> R1011 | Q1055: =DATE(B1055, MONTH(1 & L1055), D1055) -> 27612 | R1055: =DATEDIF(Q1055, DATE(2023,6,8), "Y") -> 47 | T1055: =COUNTA(Table3[[#This Row],[month]:[age]]) -> 7
A1056: Id1284 | B1056: 1975 | C1056: Aug | D1056: 21 | E1056: 1 | F1056: 8556.91 | G1056: tier - 2 | H1056: tier - 1 | I1056: R1011 | J1056: =COUNTIF(A1056:I1056, "?") -> 0 | K1056: =IF(A1056="?", "Unknown", A1056) -> Id1284 | L1056: =IF(C1056="?", "Sep", C1056) -> Aug | M1056: =IF(B1056="?",AVERAGE($B$2:$B$2344),B1056) -> 1975 | N1056: {=IF(G1056="?",INDEX($G$2:$G$2344,MODE(MATCH($G$2:$G$2344,$G$2:$G$2344,0))),G1056)} -> tier - 2 | O1056: {=IF(H1056="?",INDEX($H$2:$H$2344,MODE(MATCH($H$2:$H$2344,$H$2:$H$2344,0))),H1056)} -> tier - 1 | P1056: =IF(I1056="?", "Unknown", I1056) -> R1011 | Q1056: =DATE(B1056, MONTH(1 & L1056), D1056) -> 27627 | R1056: =DATEDIF(Q1056, DATE(2023,6,8), "Y") -> 47 | T1056: =COUNTA(Table3[[#This Row],[month]:[age]]) -> 7
A1057: Id1283 | B1057: 1988 | C1057: Sep | D1057: 21 | E1057: 3 | F1057: 8567.25 | G1057: tier - 2 | H1057: tier - 1 | I1057: R1012 | J1057: =COUNTIF(A1057:I1057, "?") -> 0 | K1057: =IF(A1057="?", "Unknown", A1057) -> Id1283 | L1057: =IF(C1057="?", "Sep", C1057) -> Sep | M1057: =IF(B1057="?",AVERAGE($B$2:$B$2344),B1057) -> 1988 | N1057: {=IF(G1057="?",INDEX($G$2:$G$2344,MODE(MATCH($G$2:$G$2344,$G$2:$G$2344,0))),G1057)} -> tier - 2 | O1057: {=IF(H1057="?",INDEX($H$2:$H$2344,MODE(MATCH($H$2:$H$2344,$H$2:$H$2344,0))),H1057)} -> tier - 1 | P1057: =IF(I1057="?", "Unknown", I1057) -> R1012 | Q1057: =DATE(B1057, MONTH(1 & L1057), D1057) -> 32407 | R1057: =DATEDIF(Q1057, DATE(2023,6,8), "Y") -> 34 | T1057: =COUNTA(Table3[[#This Row],[month]:[age]]) -> 7
A1058: Id1282 | B1058: 1975 | C1058: Sep | D1058: 26 | E1058: 1 | F1058: 8569.86 | G1058: tier - 2 | H1058: tier - 3 | I1058: R1013 | J1058: =COUNTIF(A1058:I1058, "?") -> 0 | K1058: =IF(A1058="?", "Unknown", A1058) -> Id1282 | L1058: =IF(C1058="?", "Sep", C1058) -> Sep | M1058: =IF(B1058="?",AVERAGE($B$2:$B$2344),B1058) -> 1975 | N1058: {=IF(G1058="?",INDEX($G$2:$G$2344,MODE(MATCH($G$2:$G$2344,$G$2:$G$2344,0))),G1058)} -> tier - 2 | O1058: {=IF(H1058="?",INDEX($H$2:$H$2344,MODE(MATCH($H$2:$H$2344,$H$2:$H$2344,0))),H1058)} -> tier - 3 | P1058: =IF(I1058="?", "Unknown", I1058) -> R1013 | Q1058: =DATE(B1058, MONTH(1 & L1058), D1058) -> 27663 | R1058: =DATEDIF(Q1058, DATE(2023,6,8), "Y") -> 47 | T1058: =COUNTA(Table3[[#This Row],[month]:[age]]) -> 7
A1059: Id1281 | B1059: 1982 | C1059: Dec | D1059: 6 | E1059: 3 | F1059: 8572.04 | G1059: tier - 2 | H1059: tier - 2 | I1059: R1021 | J1059: =COUNTIF(A1059:I1059, "?") -> 0 | K1059: =IF(A1059="?", "Unknown", A1059) -> Id1281 | L1059: =IF(C1059="?", "Sep", C1059) -> Dec | M1059: =IF(B1059="?",AVERAGE($B$2:$B$2344),B1059) -> 1982 | N1059: {=IF(G1059="?",INDEX($G$2:$G$2344,MODE(MATCH($G$2:$G$2344,$G$2:$G$2344,0))),G1059)} -> tier - 2 | O1059: {=IF(H1059="?",INDEX($H$2:$H$2344,MODE(MATCH($H$2:$H$2344,$H$2:$H$2344,0))),H1059)} -> tier - 2 | P1059: =IF(I1059="?", "Unknown", I1059) -> R1021 | Q1059: =DATE(B1059, MONTH(1 & L1059), D1059) -> 30291 | R1059: =DATEDIF(Q1059, DATE(2023,6,8), "Y") -> 40 | T1059: =COUNTA(Table3[[#This Row],[month]:[age]]) -> 7
A1060: Id1280 | B1060: 1987 | C1060: Nov | D1060: 11 | E1060: 3 | F1060: 8573.3 | G1060: tier - 2 | H1060: tier - 2 | I1060: R1021 | J1060: =COUNTIF(A1060:I1060, "?") -> 0 | K1060: =IF(A1060="?", "Unknown", A1060) -> Id1280 | L1060: =IF(C1060="?", "Sep", C1060) -> Nov | M1060: =IF(B1060="?",AVERAGE($B$2:$B$2344),B1060) -> 1987 | N1060: {=IF(G1060="?",INDEX($G$2:$G$2344,MODE(MATCH($G$2:$G$2344,$G$2:$G$2344,0))),G1060)} -> tier - 2 | O1060: {=IF(H1060="?",INDEX($H$2:$H$2344,MODE(MATCH($H$2:$H$2344,$H$2:$H$2344,0))),H1060)} -> tier - 2 | P1060: =IF(I1060="?", "Unknown", I1060) -> R1021 | Q1060: =DATE(B1060, MONTH(1 & L1060), D1060) -> 32092 | R1060: =DATEDIF(Q1060, DATE(2023,6,8), "Y") -> 35 | T1060: =COUNTA(Table3[[#This Row],[month]:[age]]) -> 7
A1061: Id1279 | B1061: 1983 | C1061: Dec | D1061: 30 | E1061: 5 | F1061: 8582.3 | G1061: tier - 2 | H1061: tier - 1 | I1061: R1013 | J1061: =COUNTIF(A1061:I1061, "?") -> 0 | K1061: =IF(A1061="?", "Unknown", A1061) -> Id1279 | L1061: =IF(C1061="?", "Sep", C1061) -> Dec | M1061: =IF(B1061="?",AVERAGE($B$2:$B$2344),B1061) -> 1983 | N1061: {=IF(G1061="?",INDEX($G$2:$G$2344,MODE(MATCH($G$2:$G$2344,$G$2:$G$2344,0))),G1061)} -> tier - 2 | O1061: {=IF(H1061="?",INDEX($H$2:$H$2344,MODE(MATCH($H$2:$H$2344,$H$2:$H$2344,0))),H1061)} -> tier - 1 | P1061: =IF(I1061="?", "Unknown", I1061) -> R1013 | Q1061: =DATE(B1061, MONTH(1 & L1061), D1061) -> 30680 | R1061: =DATEDIF(Q1061, DATE(2023,6,8), "Y") -> 39 | T1061: =COUNTA(Table3[[#This Row],[month]:[age]]) -> 7
A1062: Id1278 | B1062: 1983 | C1062: Jul | D1062: 25 | E1062: 5 | F1062: 8596.83 | G1062: tier - 2 | H1062: tier - 3 | I1062: R1013 | J1062: =COUNTIF(A1062:I1062, "?") -> 0 | K1062: =IF(A1062="?", "Unknown", A1062) -> Id1278 | L1062: =IF(C1062="?", "Sep", C1062) -> Jul | M1062: =IF(B1062="?",AVERAGE($B$2:$B$2344),B1062) -> 1983 | N1062: {=IF(G1062="?",INDEX($G$2:$G$2344,MODE(MATCH($G$2:$G$2344,$G$2:$G$2344,0))),G1062)} -> tier - 2 | O1062: {=IF(H1062="?",INDEX($H$2:$H$2344,MODE(MATCH($H$2:$H$2344,$H$2:$H$2344,0))),H1062)} -> tier - 3 | P1062: =IF(I1062="?", "Unknown", I1062) -> R1013 | Q1062: =DATE(B1062, MONTH(1 & L1062), D1062) -> 30522 | R1062: =DATEDIF(Q1062, DATE(2023,6,8), "Y") -> 39 | T1062: =COUNTA(Table3[[#This Row],[month]:[age]]) -> 7
A1063: Id1277 | B1063: 1973 | C1063: Jul | D1063: 11 | E1063: 0 | F1063: 8601.33 | G1063: tier - 2 | H1063: tier - 1 | I1063: R1013 | J1063: =COUNTIF(A1063:I1063, "?") -> 0 | K1063: =IF(A1063="?", "Unknown", A1063) -> Id1277 | L1063: =IF(C1063="?", "Sep", C1063) -> Jul | M1063: =IF(B1063="?",AVERAGE($B$2:$B$2344),B1063) -> 1973 | N1063: {=IF(G1063="?",INDEX($G$2:$G$2344,MODE(MATCH($G$2:$G$2344,$G$2:$G$2344,0))),G1063)} -> tier - 2 | O1063: {=IF(H1063="?",INDEX($H$2:$H$2344,MODE(MATCH($H$2:$H$2344,$H$2:$H$2344,0))),H1063)} -> tier - 1 | P1063: =IF(I1063="?", "Unknown", I1063) -> R1013 | Q1063: =DATE(B1063, MONTH(1 & L1063), D1063) -> 26856 | R1063: =DATEDIF(Q1063, DATE(2023,6,8), "Y") -> 49 | T1063: =COUNTA(Table3[[#This Row],[month]:[age]]) -> 7
A1064: Id1276 | B1064: 1977 | C1064: Sep | D1064: 24 | E1064: 2 | F1064: 8603.82 | G1064: tier - 2 | H1064: tier - 1 | I1064: R1019 | J1064: =COUNTIF(A1064:I1064, "?") -> 0 | K1064: =IF(A1064="?", "Unknown", A1064) -> Id1276 | L1064: =IF(C1064="?", "Sep", C1064) -> Sep | M1064: =IF(B1064="?",AVERAGE($B$2:$B$2344),B1064) -> 1977 | N1064: {=IF(G1064="?",INDEX($G$2:$G$2344,MODE(MATCH($G$2:$G$2344,$G$2:$G$2344,0))),G1064)} -> tier - 2 | O1064: {=IF(H1064="?",INDEX($H$2:$H$2344,MODE(MATCH($H$2:$H$2344,$H$2:$H$2344,0))),H1064)} -> tier - 1 | P1064: =IF(I1064="?", "Unknown", I1064) -> R1019 | Q1064: =DATE(B1064, MONTH(1 & L1064), D1064) -> 28392 | R1064: =DATEDIF(Q1064, DATE(2023,6,8), "Y") -> 45 | T1064: =COUNTA(Table3[[#This Row],[month]:[age]]) -> 7
A1065: Id1275 | B1065: 1977 | C1065: Nov | D1065: 12 | E1065: 2 | F1065: 8604.48 | G1065: tier - 3 | H1065: tier - 2 | I1065: R1016 | J1065: =COUNTIF(A1065:I1065, "?") -> 0 | K1065: =IF(A1065="?", "Unknown", A1065) -> Id1275 | L1065: =IF(C1065="?", "Sep", C1065) -> Nov | M1065: =IF(B1065="?",AVERAGE($B$2:$B$2344),B1065) -> 1977 | N1065: {=IF(G1065="?",INDEX($G$2:$G$2344,MODE(MATCH($G$2:$G$2344,$G$2:$G$2344,0))),G1065)} -> tier - 3 | O1065: {=IF(H1065="?",INDEX($H$2:$H$2344,MODE(MATCH($H$2:$H$2344,$H$2:$H$2344,0))),H1065)} -> tier - 2 | P1065: =IF(I1065="?", "Unknown", I1065) -> R1016 | Q1065: =DATE(B1065, MONTH(1 & L1065), D1065) -> 28441 | R1065: =DATEDIF(Q1065, DATE(2023,6,8), "Y") -> 45 | T1065: =COUNTA(Table3[[#This Row],[month]:[age]]) -> 7
A1066: Id1274 | B1066: 1977 | C1066: Oct | D1066: 15 | E1066: 3 | F1066: 8605.36 | G1066: tier - 2 | H1066: tier - 2 | I1066: R1013 | J1066: =COUNTIF(A1066:I1066, "?") -> 0 | K1066: =IF(A1066="?", "Unknown", A1066) -> Id1274 | L1066: =IF(C1066="?", "Sep", C1066) -> Oct | M1066: =IF(B1066="?",AVERAGE($B$2:$B$2344),B1066) -> 1977 | N1066: {=IF(G1066="?",INDEX($G$2:$G$2344,MODE(MATCH($G$2:$G$2344,$G$2:$G$2344,0))),G1066)} -> tier - 2 | O1066: {=IF(H1066="?",INDEX($H$2:$H$2344,MODE(MATCH($H$2:$H$2344,$H$2:$H$2344,0))),H1066)} -> tier - 2 | P1066: =IF(I1066="?", "Unknown", I1066) -> R1013 | Q1066: =DATE(B1066, MONTH(1 & L1066), D1066) -> 28413 | R1066: =DATEDIF(Q1066, DATE(2023,6,8), "Y") -> 45 | T1066: =COUNTA(Table3[[#This Row],[month]:[age]]) -> 7
... A2344: Id1 | B2344: 1968 | C2344: Oct | D2344: 12 | E2344: 0 | F2344: 63770.43 | G2344: tier - 1 | H2344: tier - 3 | I2344: R1013 | J2344: =COUNTIF(A2344:I2344, "?") -> 0 | K2344: =IF(A2344="?", "Unknown", A2344) -> Id1 | L2344: =IF(C2344="?", "Sep", C2344) -> Oct | M2344: =IF(B2344="?",AVERAGE($B$2:$B$2344),B2344) -> 1968 | N2344: {=IF(G2344="?",INDEX($G$2:$G$2344,MODE(MATCH($G$2:$G$2344,$G$2:$G$2344,0))),G2344)} -> tier - 1 | O2344: {=IF(H2344="?",INDEX($H$2:$H$2344,MODE(MATCH($H$2:$H$2344,$H$2:$H$2344,0))),H2344)} -> tier - 3 | P2344: =IF(I2344="?", "Unknown", I2344) -> R1013 | Q2344: =DATE(B2344, MONTH(1 & L2344), D2344) -> 25123 | R2344: =DATEDIF(Q2344, DATE(2023,6,8), "Y") -> 54 | T2344: =COUNTA(Table3[[#This Row],[month]:[age]]) -> 7
F2345: =SUM(F2:F2344) -> 31768896 | K2345: Count | L2345: =SUBTOTAL(103,Table3[month]) -> 2343 | M2345: =SUBTOTAL(103,Table3[year_average]) -> 2343 | N2345: =SUBTOTAL(103,Table3[hsplt_handled]) -> 2343 | O2345: =SUBTOTAL(103,Table3[city_handled]) -> 2343 | P2345: =SUBTOTAL(103,Table3[state_id]) -> 2343 | Q2345: =SUBTOTAL(103,Table3[dd/mm/yy]) -> 2343 | R2345: =SUBTOTAL(103,Table3[age]) -> 2343

Sheet HealthCare
A1: Customer ID | B1: Title | C1: First_Name | D1: Last_Name | E1: BMI | F1: HBA1C | G1: Heart Issues | H1: Any Transplants | I1: Cancer history | J1: Month | K1: Year | L1: Date | M1: DD/MM/YYY | N1: Age | O1: Children | P1: Hospital_tier | Q1: City_tier | R1: state_id | S1: charges | T1: Weight_Status | U1: No.of.surgery | V1: smoker | W1: Diabetes Level | X1: Sum
A2: Id1 | B2: =VLOOKUP(A2,'Customer Names'!$A$2:$E$2336,3,FALSE) -> Ms. | C2: =_xlfn.XLOOKUP(A2,$A$2:$A$2336,'Customer Names'!$D$2:$D$2336,"NOT FOUND") -> Kelly | D2: =_xlfn.XLOOKUP(A2,$A$2:$A$2336,'Customer Names'!$E$2:$E$2336,"NOT FOUND") -> Hawks | E2: {=_xlfn.XLOOKUP(A2,$A$2:$A$2336,Table2[BMI],"NOT FOUND")} -> 47.41 | F2: {=_xlfn.XLOOKUP(A2,$A$2:$A$2336,Table2[HBA1C],"NOT FOUND")} -> 7.47 | G2: {=_xlfn.XLOOKUP(A2,$A$2:$A$2336,Table2[Heart Issues],"NOT FOUND")} -> No | H2: {=_xlfn.XLOOKUP(A2,$A$2:$A$2336,Table2[Any Transplants],"NOT FOUND")} -> No | I2: {=_xlfn.XLOOKUP(A2,$A$2:$A$2336,Table2[Cancer history],"NOT FOUND")} -> No | J2: =_xlfn.XLOOKUP(A2,Table3[customer_no],Table3[month],"NOT FOUND") -> Oct | K2: =_xlfn.XLOOKUP(A2,Table3[customer_no],Table3[year_average],"NOT FOUND") -> 1968 | L2: {=_xlfn.XLOOKUP(A2,Table3[customer_no],'Hospitalisation Details'!$D$2:$D$2344,"NOT FOUND")} -> 12 | M2: =_xlfn.XLOOKUP(A2,Table3[customer_no],Table3[dd/mm/yy],"NOT FOUND") -> 25123 | N2: =_xlfn.XLOOKUP(A2,Table3[customer_no],Table3[age],"NOT FOUND") -> 54 | O2: {=_xlfn.XLOOKUP(A2,Table3[customer_no],'Hospitalisation Details'!$E$2:$E$2344,"NOT FOUND")} -> 0 | P2: =_xlfn.XLOOKUP(A2,Table3[customer_no],Table3[hsplt_handled],"NOT FOUND") -> tier - 1 | Q2: =_xlfn.XLOOKUP(A2,Table3[customer_no],Table3[city_handled],"NOT FOUND") -> tier - 3 | R2: =_xlfn.XLOOKUP(A2,Table3[customer_no],Table3[state_id],"NOT FOUND") -> R1013 | S2: {=_xlfn.XLOOKUP(A2,Table3[customer_no],'Hospitalisation Details'!$F$2:$F$2344,"NOT FOUND")} -> 63770.43 | T2: =_xlfn.XLOOKUP(A2,Table2[Customer ID],Table2[BMI_category],"NOT FOUND") -> Obesity | U2: =_xlfn.XLOOKUP(A2,Table2[Customer ID],Table2[no of surgery],"NOT FOUND") -> 0 | V2: =_xlfn.XLOOKUP(A2,Table2[Customer ID],Table2[smoker_missing],"NOT FOUND") -> yes | W2: =IF(F2<5.7, "Normal", IF(AND(F2>=5.7, F2<=6.4), "Prediabetes", "Diabetes")) -> Diabetes | X2: =SUM(Table5[[#This Row],[Title]:[Diabetes Level]]) -> 90982.31
A3: Id2 | B3: =VLOOKUP(A3,'Customer Names'!$A$2:$E$2336,3,FALSE) -> Mr. | C3: =_xlfn.XLOOKUP(A3,$A$2:$A$2336,'Customer Names'!$D$2:$D$2336,"NOT FOUND") -> Matthew D | D3: =_xlfn.XLOOKUP(A3,$A$2:$A$2336,'Customer Names'!$E$2:$E$2336,"NOT FOUND") -> Lehner | E3: {=_xlfn.XLOOKUP(A3,$A$2:$A$2336,Table2[BMI],"NOT FOUND")} -> 30.36 | F3: {=_xlfn.XLOOKUP(A3,$A$2:$A$2336,Table2[HBA1C],"NOT FOUND")} -> 5.77 | G3: {=_xlfn.XLOOKUP(A3,$A$2:$A$2336,Table2[Heart Issues],"NOT FOUND")} -> No | H3: {=_xlfn.XLOOKUP(A3,$A$2:$A$2336,Table2[Any Transplants],"NOT FOUND")} -> No | I3: {=_xlfn.XLOOKUP(A3,$A$2:$A$2336,Table2[Cancer history],"NOT FOUND")} -> No | J3: =_xlfn.XLOOKUP(A3,Table3[customer_no],Table3[month],"NOT FOUND") -> Jun | K3: =_xlfn.XLOOKUP(A3,Table3[customer_no],Table3[year_average],"NOT FOUND") -> 1977 | L3: {=_xlfn.XLOOKUP(A3,Table3[customer_no],'Hospitalisation Details'!$D$2:$D$2344,"NOT FOUND")} -> 8 | M3: =_xlfn.XLOOKUP(A3,Table3[customer_no],Table3[dd/mm/yy],"NOT FOUND") -> 28284 | N3: =_xlfn.XLOOKUP(A3,Table3[customer_no],Table3[age],"NOT FOUND") -> 46 | O3: {=_xlfn.XLOOKUP(A3,Table3[customer_no],'Hospitalisation Details'!$E$2:$E$2344,"NOT FOUND")} -> 0 | P3: =_xlfn.XLOOKUP(A3,Table3[customer_no],Table3[hsplt_handled],"NOT FOUND") -> tier - 2 | Q3: =_xlfn.XLOOKUP(A3,Table3[customer_no],Table3[city_handled],"NOT FOUND") -> tier - 3 | R3: =_xlfn.XLOOKUP(A3,Table3[customer_no],Table3[state_id],"NOT FOUND") -> R1013 | S3: {=_xlfn.XLOOKUP(A3,Table3[customer_no],'Hospitalisation Details'!$F$2:$F$2344,"NOT FOUND")} -> 62592.87 | T3: =_xlfn.XLOOKUP(A3,Table2[Customer ID],Table2[BMI_category],"NOT FOUND") -> Obesity | U3: =_xlfn.XLOOKUP(A3,Table2[Customer ID],Table2[no of surgery],"NOT FOUND") -> 0 | V3: =_xlfn.XLOOKUP(A3,Table2[Customer ID],Table2[smoker_missing],"NOT FOUND") -> yes | W3: =IF(F3<5.7, "Normal", IF(AND(F3>=5.7, F3<=6.4), "Prediabetes", "Diabetes")) -> Prediabetes | X3: =SUM(Table5[[#This Row],[Title]:[Diabetes Level]]) -> 92944
A4: Id3 | B4: =VLOOKUP(A4,'Customer Names'!$A$2:$E$2336,3,FALSE) -> Mr. | C4: =_xlfn.XLOOKUP(A4,$A$2:$A$2336,'Customer Names'!$D$2:$D$2336,"NOT FOUND") -> Phil | D4: =_xlfn.XLOOKUP(A4,$A$2:$A$2336,'Customer Names'!$E$2:$E$2336,"NOT FOUND") -> Lu | E4: {=_xlfn.XLOOKUP(A4,$A$2:$A$2336,Table2[BMI],"NOT FOUND")} -> 34.485 | F4: {=_xlfn.XLOOKUP(A4,$A$2:$A$2336,Table2[HBA1C],"NOT FOUND")} -> 11.87 | G4: {=_xlfn.XLOOKUP(A4,$A$2:$A$2336,Table2[Heart Issues],"NOT FOUND")} -> yes | H4: {=_xlfn.XLOOKUP(A4,$A$2:$A$2336,Table2[Any Transplants],"NOT FOUND")} -> No | I4: {=_xlfn.XLOOKUP(A4,$A$2:$A$2336,Table2[Cancer history],"NOT FOUND")} -> No | J4: =_xlfn.XLOOKUP(A4,Table3[customer_no],Table3[month],"NOT FOUND") -> Sep | K4: =_xlfn.XLOOKUP(A4,Table3[customer_no],Table3[year_average],"NOT FOUND") -> 1970 | L4: {=_xlfn.XLOOKUP(A4,Table3[customer_no],'Hospitalisation Details'!$D$2:$D$2344,"NOT FOUND")} -> 11 | M4: =_xlfn.XLOOKUP(A4,Table3[customer_no],Table3[dd/mm/yy],"NOT FOUND") -> 25822 | N4: =_xlfn.XLOOKUP(A4,Table3[customer_no],Table3[age],"NOT FOUND") -> 52 | O4: {=_xlfn.XLOOKUP(A4,Table3[customer_no],'Hospitalisation Details'!$E$2:$E$2344,"NOT FOUND")} -> 3 | P4: =_xlfn.XLOOKUP(A4,Table3[customer_no],Table3[hsplt_handled],"NOT FOUND") -> tier - 1 | Q4: =_xlfn.XLOOKUP(A4,Table3[customer_no],Table3[city_handled],"NOT FOUND") -> tier - 1 | R4: =_xlfn.XLOOKUP(A4,Table3[customer_no],Table3[state_id],"NOT FOUND") -> R1012 | S4: {=_xlfn.XLOOKUP(A4,Table3[customer_no],'Hospitalisation Details'!$F$2:$F$2344,"NOT FOUND")} -> 60021.4 | T4: =_xlfn.XLOOKUP(A4,Table2[Customer ID],Table2[BMI_category],"NOT FOUND") -> Obesity | U4: =_xlfn.XLOOKUP(A4,Table2[Customer ID],Table2[no of surgery],"NOT FOUND") -> 2 | V4: =_xlfn.XLOOKUP(A4,Table2[Customer ID],Table2[smoker_missing],"NOT FOUND") -> yes | W4: =IF(F4<5.7, "Normal", IF(AND(F4>=5.7, F4<=6.4), "Prediabetes", "Diabetes")) -> Diabetes | X4: =SUM(Table5[[#This Row],[Title]:[Diabetes Level]]) -> 87927.755
A5: Id4 | B5: =VLOOKUP(A5,'Customer Names'!$A$2:$E$2336,3,FALSE) -> Ms. | C5: =_xlfn.XLOOKUP(A5,$A$2:$A$2336,'Customer Names'!$D$2:$D$2336,"NOT FOUND") -> Kelsey | D5: =_xlfn.XLOOKUP(A5,$A$2:$A$2336,'Customer Names'!$E$2:$E$2336,"NOT FOUND") -> Osborne | E5: {=_xlfn.XLOOKUP(A5,$A$2:$A$2336,Table2[BMI],"NOT FOUND")} -> 38.095 | F5: {=_xlfn.XLOOKUP(A5,$A$2:$A$2336,Table2[HBA1C],"NOT FOUND")} -> 6.05 | G5: {=_xlfn.XLOOKUP(A5,$A$2:$A$2336,Table2[Heart Issues],"NOT FOUND")} -> No | H5: {=_xlfn.XLOOKUP(A5,$A$2:$A$2336,Table2[Any Transplants],"NOT FOUND")} -> No | I5: {=_xlfn.XLOOKUP(A5,$A$2:$A$2336,Table2[Cancer history],"NOT FOUND")} -> No | J5: =_xlfn.XLOOKUP(A5,Table3[customer_no],Table3[month],"NOT FOUND") -> Jun | K5: =_xlfn.XLOOKUP(A5,Table3[customer_no],Table3[year_average],"NOT FOUND") -> 1991 | L5: {=_xlfn.XLOOKUP(A5,Table3[customer_no],'Hospitalisation Details'!$D$2:$D$2344,"NOT FOUND")} -> 6 | M5: =_xlfn.XLOOKUP(A5,Table3[customer_no],Table3[dd/mm/yy],"NOT FOUND") -> 33395 | N5: =_xlfn.XLOOKUP(A5,Table3[customer_no],Table3[age],"NOT FOUND") -> 32 | O5: {=_xlfn.XLOOKUP(A5,Table3[customer_no],'Hospitalisation Details'!$E$2:$E$2344,"NOT FOUND")} -> 1 | P5: =_xlfn.XLOOKUP(A5,Table3[customer_no],Table3[hsplt_handled],"NOT FOUND") -> tier - 1 | Q5: =_xlfn.XLOOKUP(A5,Table3[customer_no],Table3[city_handled],"NOT FOUND") -> tier - 3 | R5: =_xlfn.XLOOKUP(A5,Table3[customer_no],Table3[state_id],"NOT FOUND") -> R1024 | S5: {=_xlfn.XLOOKUP(A5,Table3[customer_no],'Hospitalisation Details'!$F$2:$F$2344,"NOT FOUND")} -> 58571.07 | T5: =_xlfn.XLOOKUP(A5,Table2[Customer ID],Table2[BMI_category],"NOT FOUND") -> Obesity | U5: =_xlfn.XLOOKUP(A5,Table2[Customer ID],Table2[no of surgery],"NOT FOUND") -> 0 | V5: =_xlfn.XLOOKUP(A5,Table2[Customer ID],Table2[smoker_missing],"NOT FOUND") -> yes | W5: =IF(F5<5.7, "Normal", IF(AND(F5>=5.7, F5<=6.4), "Prediabetes", "Diabetes")) -> Prediabetes | X5: =SUM(Table5[[#This Row],[Title]:[Diabetes Level]]) -> 94040.215
A6: Id5 | B6: =VLOOKUP(A6,'Customer Names'!$A$2:$E$2336,3,FALSE) -> Ms. | C6: =_xlfn.XLOOKUP(A6,$A$2:$A$2336,'Customer Names'!$D$2:$D$2336,"NOT FOUND") -> Kristyn | D6: =_xlfn.XLOOKUP(A6,$A$2:$A$2336,'Customer Names'!$E$2:$E$2336,"NOT FOUND") -> Kadala | E6: {=_xlfn.XLOOKUP(A6,$A$2:$A$2336,Table2[BMI],"NOT FOUND")} -> 35.53 | F6: {=_xlfn.XLOOKUP(A6,$A$2:$A$2336,Table2[HBA1C],"NOT FOUND")} -> 5.45 | G6: {=_xlfn.XLOOKUP(A6,$A$2:$A$2336,Table2[Heart Issues],"NOT FOUND")} -> No | H6: {=_xlfn.XLOOKUP(A6,$A$2:$A$2336,Table2[Any Transplants],"NOT FOUND")} -> No | I6: {=_xlfn.XLOOKUP(A6,$A$2:$A$2336,Table2[Cancer history],"NOT FOUND")} -> No | J6: =_xlfn.XLOOKUP(A6,Table3[customer_no],Table3[month],"NOT FOUND") -> Jun | K6: =_xlfn.XLOOKUP(A6,Table3[customer_no],Table3[year_average],"NOT FOUND") -> 1989 | L6: {=_xlfn.XLOOKUP(A6,Table3[customer_no],'Hospitalisation Details'!$D$2:$D$2344,"NOT FOUND")} -> 19 | M6: =_xlfn.XLOOKUP(A6,Table3[customer_no],Table3[dd/mm/yy],"NOT FOUND") -> 32678 | N6: =_xlfn.XLOOKUP(A6,Table3[customer_no],Table3[age],"NOT FOUND") -> 33 | O6: {=_xlfn.XLOOKUP(A6,Table3[customer_no],'Hospitalisation Details'!$E$2:$E$2344,"NOT FOUND")} -> 0 | P6: =_xlfn.XLOOKUP(A6,Table3[customer_no],Table3[hsplt_handled],"NOT FOUND") -> tier - 1 | Q6: =_xlfn.XLOOKUP(A6,Table3[customer_no],Table3[city_handled],"NOT FOUND") -> tier - 2 | R6: =_xlfn.XLOOKUP(A6,Table3[customer_no],Table3[state_id],"NOT FOUND") -> R1012 | S6: {=_xlfn.XLOOKUP(A6,Table3[customer_no],'Hospitalisation Details'!$F$2:$F$2344,"NOT FOUND")} -> 55135.4 | T6: =_xlfn.XLOOKUP(A6,Table2[Customer ID],Table2[BMI_category],"NOT FOUND") -> Obesity | U6: =_xlfn.XLOOKUP(A6,Table2[Customer ID],Table2[no of surgery],"NOT FOUND") -> 0 | V6: =_xlfn.XLOOKUP(A6,Table2[Customer ID],Table2[smoker_missing],"NOT FOUND") -> yes | W6: =IF(F6<5.7, "Normal", IF(AND(F6>=5.7, F6<=6.4), "Prediabetes", "Diabetes")) -> Normal | X6: =SUM(Table5[[#This Row],[Title]:[Diabetes Level]]) -> 89895.38
A7: Id6 | B7: =VLOOKUP(A7,'Customer Names'!$A$2:$E$2336,3,FALSE) -> Mr. | C7: =_xlfn.XLOOKUP(A7,$A$2:$A$2336,'Customer Names'!$D$2:$D$2336,"NOT FOUND") -> Russell B. | D7: =_xlfn.XLOOKUP(A7,$A$2:$A$2336,'Customer Names'!$E$2:$E$2336,"NOT FOUND") -> Baker | E7: {=_xlfn.XLOOKUP(A7,$A$2:$A$2336,Table2[BMI],"NOT FOUND")} -> 32.8 | F7: {=_xlfn.XLOOKUP(A7,$A$2:$A$2336,Table2[HBA1C],"NOT FOUND")} -> 6.59 | G7: {=_xlfn.XLOOKUP(A7,$A$2:$A$2336,Table2[Heart Issues],"NOT FOUND")} -> No | H7: {=_xlfn.XLOOKUP(A7,$A$2:$A$2336,Table2[Any Transplants],"NOT FOUND")} -> No | I7: {=_xlfn.XLOOKUP(A7,$A$2:$A$2336,Table2[Cancer history],"NOT FOUND")} -> No | J7: =_xlfn.XLOOKUP(A7,Table3[customer_no],Table3[month],"NOT FOUND") -> Aug | K7: =_xlfn.XLOOKUP(A7,Table3[customer_no],Table3[year_average],"NOT FOUND") -> 1962 | L7: {=_xlfn.XLOOKUP(A7,Table3[customer_no],'Hospitalisation Details'!$D$2:$D$2344,"NOT FOUND")} -> 4 | M7: =_xlfn.XLOOKUP(A7,Table3[customer_no],Table3[dd/mm/yy],"NOT FOUND") -> 22862 | N7: =_xlfn.XLOOKUP(A7,Table3[customer_no],Table3[age],"NOT FOUND") -> 60 | O7: {=_xlfn.XLOOKUP(A7,Table3[customer_no],'Hospitalisation Details'!$E$2:$E$2344,"NOT FOUND")} -> 0 | P7: =_xlfn.XLOOKUP(A7,Table3[customer_no],Table3[hsplt_handled],"NOT FOUND") -> tier - 1 | Q7: =_xlfn.XLOOKUP(A7,Table3[customer_no],Table3[city_handled],"NOT FOUND") -> tier - 3 | R7: =_xlfn.XLOOKUP(A7,Table3[customer_no],Table3[state_id],"NOT FOUND") -> R1011 | S7: {=_xlfn.XLOOKUP(A7,Table3[customer_no],'Hospitalisation Details'!$F$2:$F$2344,"NOT FOUND")} -> 52590.83 | T7: =_xlfn.XLOOKUP(A7,Table2[Customer ID],Table2[BMI_category],"NOT FOUND") -> Obesity | U7: =_xlfn.XLOOKUP(A7,Table2[Customer ID],Table2[no of surgery],"NOT FOUND") -> 0 | V7: =_xlfn.XLOOKUP(A7,Table2[Customer ID],Table2[smoker_missing],"NOT FOUND") -> yes | W7: =IF(F7<5.7, "Normal", IF(AND(F7>=5.7, F7<=6.4), "Prediabetes", "Diabetes")) -> Diabetes | X7: =SUM(Table5[[#This Row],[Title]:[Diabetes Level]]) -> 77518.22
A8: Id7 | B8: =VLOOKUP(A8,'Customer Names'!$A$2:$E$2336,3,FALSE) -> Mr. | C8: =_xlfn.XLOOKUP(A8,$A$2:$A$2336,'Customer Names'!$D$2:$D$2336,"NOT FOUND") -> Scott | D8: =_xlfn.XLOOKUP(A8,$A$2:$A$2336,'Customer Names'!$E$2:$E$2336,"NOT FOUND") -> Macpherson | E8: {=_xlfn.XLOOKUP(A8,$A$2:$A$2336,Table2[BMI],"NOT FOUND")} -> 36.4 | F8: {=_xlfn.XLOOKUP(A8,$A$2:$A$2336,Table2[HBA1C],"NOT FOUND")} -> 6.07 | G8: {=_xlfn.XLOOKUP(A8,$A$2:$A$2336,Table2[Heart Issues],"NOT FOUND")} -> No | H8: {=_xlfn.XLOOKUP(A8,$A$2:$A$2336,Table2[Any Transplants],"NOT FOUND")} -> No | I8: {=_xlfn.XLOOKUP(A8,$A$2:$A$2336,Table2[Cancer history],"NOT FOUND")} -> No | J8: =_xlfn.XLOOKUP(A8,Table3[customer_no],Table3[month],"NOT FOUND") -> Oct | K8: =_xlfn.XLOOKUP(A8,Table3[customer_no],Table3[year_average],"NOT FOUND") -> 1994 | L8: {=_xlfn.XLOOKUP(A8,Table3[customer_no],'Hospitalisation Details'!$D$2:$D$2344,"NOT FOUND")} -> 27 | M8: =_xlfn.XLOOKUP(A8,Table3[customer_no],Table3[dd/mm/yy],"NOT FOUND") -> 34634 | N8: =_xlfn.XLOOKUP(A8,Table3[customer_no],Table3[age],"NOT FOUND") -> 28 | O8: {=_xlfn.XLOOKUP(A8,Table3[customer_no],'Hospitalisation Details'!$E$2:$E$2344,"NOT FOUND")} -> 1 | P8: =_xlfn.XLOOKUP(A8,Table3[customer_no],Table3[hsplt_handled],"NOT FOUND") -> tier - 1 | Q8: =_xlfn.XLOOKUP(A8,Table3[customer_no],Table3[city_handled],"NOT FOUND") -> tier - 3 | R8: =_xlfn.XLOOKUP(A8,Table3[customer_no],Table3[state_id],"NOT FOUND") -> R1011 | S8: {=_xlfn.XLOOKUP(A8,Table3[customer_no],'Hospitalisation Details'!$F$2:$F$2344,"NOT FOUND")} -> 51194.56 | T8: =_xlfn.XLOOKUP(A8,Table2[Customer ID],Table2[BMI_category],"NOT FOUND") -> Obesity | U8: =_xlfn.XLOOKUP(A8,Table2[Customer ID],Table2[no of surgery],"NOT FOUND") -> 0 | V8: =_xlfn.XLOOKUP(A8,Table2[Customer ID],Table2[smoker_missing],"NOT FOUND") -> yes | W8: =IF(F8<5.7, "Normal", IF(AND(F8>=5.7, F8<=6.4), "Prediabetes", "Diabetes")) -> Prediabetes | X8: =SUM(Table5[[#This Row],[Title]:[Diabetes Level]]) -> 87921.03
A9: Id8 | B9: =VLOOKUP(A9,'Customer Names'!$A$2:$E$2336,3,FALSE) -> Mr. | C9: =_xlfn.XLOOKUP(A9,$A$2:$A$2336,'Customer Names'!$D$2:$D$2336,"NOT FOUND") -> Stephen | D9: =_xlfn.XLOOKUP(A9,$A$2:$A$2336,'Customer Names'!$E$2:$E$2336,"NOT FOUND") -> Hallman | E9: {=_xlfn.XLOOKUP(A9,$A$2:$A$2336,Table2[BMI],"NOT FOUND")} -> 36.96 | F9: {=_xlfn.XLOOKUP(A9,$A$2:$A$2336,Table2[HBA1C],"NOT FOUND")} -> 7.93 | G9: {=_xlfn.XLOOKUP(A9,$A$2:$A$2336,Table2[Heart Issues],"NOT FOUND")} -> No | H9: {=_xlfn.XLOOKUP(A9,$A$2:$A$2336,Table2[Any Transplants],"NOT FOUND")} -> No | I9: {=_xlfn.XLOOKUP(A9,$A$2:$A$2336,Table2[Cancer history],"NOT FOUND")} -> No | J9: =_xlfn.XLOOKUP(A9,Table3[customer_no],Table3[month],"NOT FOUND") -> Jun | K9: =_xlfn.XLOOKUP(A9,Table3[customer_no],Table3[year_average],"NOT FOUND") -> 1958 | L9: {=_xlfn.XLOOKUP(A9,Table3[customer_no],'Hospitalisation Details'!$D$2:$D$2344,"NOT FOUND")} -> 27 | M9: =_xlfn.XLOOKUP(A9,Table3[customer_no],Table3[dd/mm/yy],"NOT FOUND") -> 21363 | N9: =_xlfn.XLOOKUP(A9,Table3[customer_no],Table3[age],"NOT FOUND") -> 64 | O9: {=_xlfn.XLOOKUP(A9,Table3[customer_no],'Hospitalisation Details'!$E$2:$E$2344,"NOT FOUND")} -> 2 | P9: =_xlfn.XLOOKUP(A9,Table3[customer_no],Table3[hsplt_handled],"NOT FOUND") -> tier - 2 | Q9: =_xlfn.XLOOKUP(A9,Table3[customer_no],Table3[city_handled],"NOT FOUND") -> tier - 2 | R9: =_xlfn.XLOOKUP(A9,Table3[customer_no],Table3[state_id],"NOT FOUND") -> R1013 | S9: {=_xlfn.XLOOKUP(A9,Table3[customer_no],'Hospitalisation Details'!$F$2:$F$2344,"NOT FOUND")} -> 49577.66 | T9: =_xlfn.XLOOKUP(A9,Table2[Customer ID],Table2[BMI_category],"NOT FOUND") -> Obesity | U9: =_xlfn.XLOOKUP(A9,Table2[Customer ID],Table2[no of surgery],"NOT FOUND") -> 3 | V9: =_xlfn.XLOOKUP(A9,Table2[Customer ID],Table2[smoker_missing],"NOT FOUND") -> yes | W9: =IF(F9<5.7, "Normal", IF(AND(F9>=5.7, F9<=6.4), "Prediabetes", "Diabetes")) -> Diabetes | X9: =SUM(Table5[[#This Row],[Title]:[Diabetes Level]]) -> 73039.55
